Workbook

Sheet Intro & Core Assumptions
B4: Company Description | C4: Sun Pharmaceutical Industries Ltd
B5: ISIN Code | C5: INE044A01036
B6: Sector Name | C6: Healthcare
B7: Industry | C7: Pharmaceutical
B8: Exchange Name | C8: BSE: 524715, NSE: SUNPHARMA
B9: Website | C9: hhttps://sunpharma.com/
B10: Company Description | C10: Sun Pharmaceutical Industries Ltd is engaged in the business of manufacturing, developing and marketing a wide range of branded and generic formulations and Active Pharma Ingredients (APIs). The company and its subsidiaries has various manufacturing facilities spread across the world with trading and other incidental and related activities extending to global market.It is the largest pharmaceutical company in India.
B11: Current Market Price | C11: 1840
B14: Scenario | D14: Case
B15: Base case | D15: =IF(B15="Best case",1,IF(B15="Base case",2,3)) -> 2
B18: Company data
B19: Particulars | D19: Amount
B20: No of Outstanding shares | C20: Nos | D20: 2406292857
B21: Face Value per share | C21: Rs. | D21: 1
B22: Current Market Price | C22: Rs. | D22: =C11 -> 1840
B23: Market Capitalisation | C23: INR in crs | D23: =D20*D22/10^7 -> 442757.89
B25: Assumptions
B26: Increase in Sales volume growth rate | C26: % | D26: =Assumptions!G10 -> 0.084161961
B27: Perpetual Growth rate | C27: % | D27: ='DCF Valuation'!C26 -> 0.04
B28: 10 year Bond yield rate | C28: % | D28: =WACC!K27 -> 0.0689
B29: Interest rate | C29: % | D29: =Assumptions!G15 -> 0.081301899
B30: Pharma sector growth rate (25-30) | C30: % | D30: 0.1
B32: Company Sales volume data
B33: Year | D33: Revenue in Crs
B34: 2021 | D34: 33498.14
B35: =B34+1 -> 2022 | D35: 38654.49
B36: =B35+1 -> 2023 | D36: 43885.68
B37: =B36+1 -> 2024 | D37: 48496.85
B38: =B37+1 -> 2025 | D38: 52578.44
B41: Sheet | C41: Assumptions
B42: Revenue Buildup | C42: Revenue is increasing by 10% (base case) from 2025 to 2030 (according to IBEF ) after that the growth rate is tapered by 12.25% every year till 2035 when it reaches to 4% perpetual growth rate.
C43: Bull case growth rate is taken as +5% of base case and worst case growth rate is taken as -5% of base case.
B44: Income Statement | C44: All costs except finance costs, tax, and depreciation have been forecasted as a % of Total Revenue and using the average percantage of historical years for forecasting.
C45: Finance costs have been forecasted as a % of the sum of long-term and short-term borrowings using the latest year’s percentage.
C46: Tax expense has been forecasted by increasing the effective tax rate (calculated as a % of PBT) by 1% and then increase by 1% after every 2 years.
C47: Dividend has been forecasted using the average percentage of last 3 years and then multiply that percentage with current PAT.
C48: Depreciation and ammortization has been forecasted by using latest deprecaiation on Fixed Assets and the increasing it by 1% and then increasing by 1% once after every 2 years.
C49: Other Income has been forecasted as the average % of sales of the last three years, while the share of profit/loss from associates and joint ventures has been forecasted using the average % of the last five years.
B50: Balance Sheet | C50: PPE has been calculated as per its schedule, while Trade Receivables have been forecasted as the average % of sales of historical years, and Inventories and Trade Payables have been forecasted as a % of COGS of historical years.
C51: Reserves have been forecasted based on the previous year’s reserves, after adding retained earnings generated from net profit after dividend distribution.
...

Sheet Assumptions
B7: Particulars | C7: Historical | H7: Forecasting
C8: 44286 | D8: 44651 | E8: 45016 | F8: 45382 | G8: 45747 | H8: 46112 | I8: 46477 | J8: 46843 | K8: 47208 | L8: 47573 | M8: =L8+365 -> 47938 | N8: =M8+365 -> 48303 | O8: =N8+365 -> 48668 | P8: =O8+365 -> 49033 | Q8: =P8+365 -> 49398
H9: Base Case
B10: Sales Growth (y-o-y increase) | C10: - | D10: =('Income Statement'!D9-'Income Statement'!C9)/'Income Statement'!C9 -> 0.15392944 | E10: =('Income Statement'!E9-'Income Statement'!D9)/'Income Statement'!D9 -> 0.13533201 | F10: =('Income Statement'!F9-'Income Statement'!E9)/'Income Statement'!E9 -> 0.10507232 | G10: =('Income Statement'!G9-'Income Statement'!F9)/'Income Statement'!F9 -> 0.084161961 | H10: =IF($H$9="Base Case",'Revenue Buildup'!E8,IF(Assumptions!$H$9="Bull Case",'Revenue Buildup'!E9,'Revenue Buildup'!E10)) -> 0.1 | I10: =IF($H$9="Base Case",'Revenue Buildup'!F8,IF(Assumptions!$H$9="Bull Case",'Revenue Buildup'!F9,'Revenue Buildup'!F10)) -> 0.1 | J10: =IF($H$9="Base Case",'Revenue Buildup'!G8,IF(Assumptions!$H$9="Bull Case",'Revenue Buildup'!G9,'Revenue Buildup'!G10)) -> 0.1 | K10: =IF($H$9="Base Case",'Revenue Buildup'!H8,IF(Assumptions!$H$9="Bull Case",'Revenue Buildup'!H9,'Revenue Buildup'!H10)) -> 0.1 | L10: =IF($H$9="Base Case",'Revenue Buildup'!I8,IF(Assumptions!$H$9="Bull Case",'Revenue Buildup'!I9,'Revenue Buildup'!I10)) -> 0.1 | M10: =IF($H$9="Base Case",'Revenue Buildup'!J8,IF(Assumptions!$H$9="Bull Case",'Revenue Buildup'!J9,'Revenue Buildup'!J10)) -> 0.08325 | N10: =IF($H$9="Base Case",'Revenue Buildup'!K8,IF(Assumptions!$H$9="Bull Case",'Revenue Buildup'!K9,'Revenue Buildup'!K10)) -> 0.069305625 | O10: =IF($H$9="Base Case",'Revenue Buildup'!L8,IF(Assumptions!$H$9="Bull Case",'Revenue Buildup'!L9,'Revenue Buildup'!L10)) -> 0.057696933 | ... Q10: =IF($H$9="Base Case",'Revenue Buildup'!N8,IF(Assumptions!$H$9="Bull Case",'Revenue Buildup'!N9,'Revenue Buildup'!N10)) -> 0.03998722
B11: Cost of goods Sold (% of sales) | C11: ='Income Statement'!C10/'Income Statement'!C9 -> 0.25941978 | D11: ='Income Statement'!D10/'Income Statement'!D9 -> 0.26779657 | E11: ='Income Statement'!E10/'Income Statement'!E9 -> 0.24295305 | F11: ='Income Statement'!F10/'Income Statement'!F9 -> 0.21986191 | G11: ='Income Statement'!G10/'Income Statement'!G9 -> 0.20440622 | H11: =AVERAGE(C11:G11) -> 0.23888751 | I11: =H11 -> 0.23888751 | J11: =I11 -> 0.23888751 | K11: =J11 -> 0.23888751 | L11: =K11 -> 0.23888751 | M11: =L11 -> 0.23888751 | N11: =M11 -> 0.23888751 | O11: =N11 -> 0.23888751 | P11: =O11 -> 0.23888751 | Q11: =P11 -> 0.23888751
B12: Employee Cost (% of sales) | C12: ='Income Statement'!C12/'Income Statement'!C9 -> 0.20485406 | D12: ='Income Statement'!D12/'Income Statement'!D9 -> 0.18887405 | E12: ='Income Statement'!E12/'Income Statement'!E9 -> 0.18903729 | F12: ='Income Statement'!F12/'Income Statement'!F9 -> 0.19442624 | G12: ='Income Statement'!G12/'Income Statement'!G9 -> 0.18968079 | H12: =AVERAGE(C12:G12) -> 0.19337448 | I12: =H12 -> 0.19337448 | J12: =I12 -> 0.19337448 | K12: =J12 -> 0.19337448 | L12: =K12 -> 0.19337448 | M12: =L12 -> 0.19337448 | N12: =M12 -> 0.19337448 | O12: =N12 -> 0.19337448 | P12: =O12 -> 0.19337448 | Q12: =P12 -> 0.19337448
B13: Selling,Admin & Other Expenses (% of Sales) | C13: ='Income Statement'!C13/'Income Statement'!C9 -> 0.28294437 | D13: ='Income Statement'!D13/'Income Statement'!D9 -> 0.2783211 | E13: ='Income Statement'!E13/'Income Statement'!E9 -> 0.29974698 | F13: ='Income Statement'!F13/'Income Statement'!F9 -> 0.31792127 | G13: ='Income Statement'!G13/'Income Statement'!G9 -> 0.31898626 | H13: =AVERAGE(C13:G13) -> 0.29958399 | I13: =H13 -> 0.29958399 | J13: =I13 -> 0.29958399 | K13: =J13 -> 0.29958399 | L13: =K13 -> 0.29958399 | M13: =L13 -> 0.29958399 | N13: =M13 -> 0.29958399 | O13: =N13 -> 0.29958399 | P13: =O13 -> 0.29958399 | Q13: =P13 -> 0.29958399
B14: Depreciation & Ammortization (% of Fixed Assets) | C14: ='Income Statement'!C15/Schedules!C18 -> 0.16889648 | D14: ='Income Statement'!D15/'Balance Sheet'!D11 -> 0.20945209 | E14: ='Income Statement'!E15/'Balance Sheet'!E11 -> 0.24388558 | F14: ='Income Statement'!F15/'Balance Sheet'!F11 -> 0.24605837 | G14: ='Income Statement'!G15/'Balance Sheet'!G11 -> 0.25267947 | H14: =G14*(101%) -> 0.25520626 | I14: =H14 -> 0.25520626 | J14: =I14*(101%) -> 0.25775833 | K14: =J14 -> 0.25775833 | L14: =K14*(101%) -> 0.26033591 | M14: =L14 -> 0.26033591 | N14: =M14*(101%) -> 0.26293927 | O14: =N14 -> 0.26293927 | P14: =O14*(101.5%) -> 0.26688336 | Q14: =P14 -> 0.26688336
B15: Interest Rate (% of Debt) | C15: =Schedules!C27/Schedules!C24 -> 0.042305805 | D15: =Schedules!D27/Schedules!D24 -> 0.036143245 | E15: =Schedules!E27/Schedules!E24 -> 0.18480912 | F15: =Schedules!F27/Schedules!F24 -> 0.03847606 | G15: =Schedules!G27/Schedules!G24 -> 0.081301899 | H15: =G15 -> 0.081301899 | I15: =H15 -> 0.081301899 | J15: =I15 -> 0.081301899 | K15: =J15 -> 0.081301899 | L15: =K15 -> 0.081301899 | M15: =L15 -> 0.081301899 | N15: =M15 -> 0.081301899 | O15: =N15 -> 0.081301899 | ... Q15: =P15 -> 0.081301899
B16: Dividend Payout Ratio (% of PAT) | C16: =-(CFS!D38/'Income Statement'!C22) -> 0.69803067 | D16: =-(CFS!E38/'Income Statement'!D22) -> 0.64001499 | E16: =-(CFS!F38/'Income Statement'!E22) -> 0.29598822 | F16: =-(CFS!G38/'Income Statement'!F22) -> 0.30184193 | G16: =-(CFS!H38/'Income Statement'!G22) -> 0.32990264 | H16: =AVERAGE(E16:G16) -> 0.30924427 | I16: =H16 -> 0.30924427 | J16: =I16 -> 0.30924427 | K16: =J16 -> 0.30924427 | L16: =K16 -> 0.30924427 | M16: =L16 -> 0.30924427 | N16: =M16 -> 0.30924427 | O16: =N16 -> 0.30924427 | P16: =O16 -> 0.30924427 | Q16: =P16 -> 0.30924427
A17: 42500 | B17: Other Income (% of Revenue) | C17: - | D17: - | E17: ='Income Statement'!E18/'Income Statement'!E9 -> 0.0076783589 | F17: ='Income Statement'!F18/'Income Statement'!F9 -> 0.018475427 | G17: ='Income Statement'!G18/'Income Statement'!G9 -> 0.02800996 | H17: =AVERAGE(E17:G17) -> 0.018054582 | I17: =H17 -> 0.018054582 | J17: =I17 -> 0.018054582 | K17: =J17 -> 0.018054582 | L17: =K17 -> 0.018054582 | M17: =L17 -> 0.018054582 | N17: =M17 -> 0.018054582 | O17: =N17 -> 0.018054582 | P17: =O17 -> 0.018054582 | Q17: =P17 -> 0.018054582
B18: Tax Rate (% of PBT) | C18: ='Income Statement'!C20/'Income Statement'!C19 -> 0.18385923 | D18: ='Income Statement'!D20/'Income Statement'!D19 -> 0.23999625 | E18: ='Income Statement'!E20/'Income Statement'!E19 -> 0.090088357 | F18: ='Income Statement'!F20/'Income Statement'!F19 -> 0.12982181 | G18: ='Income Statement'!G20/'Income Statement'!G19 -> 0.20157096 | H18: =G18*(101%) -> 0.20358667 | I18: =H18 -> 0.20358667 | J18: =I18*(101%) -> 0.20562253 | K18: =J18 -> 0.20562253 | L18: =K18*(101%) -> 0.20767876 | M18: =L18 -> 0.20767876 | N18: =M18*(101%) -> 0.20975555 | O18: =N18 -> 0.20975555 | P18: =O18*(101%) -> 0.2118531 | Q18: =P18 -> 0.2118531
B19: Share of (loss)/gain of associates or JV (% of sales) | C19: ='Income Statement'!C21/'Income Statement'!C9 -> -0.00036808014 | D19: ='Income Statement'!D21/'Income Statement'!D9 -> -0.00042789337 | E19: ='Income Statement'!E21/'Income Statement'!E9 -> -0.0010914722 | F19: ='Income Statement'!F21/'Income Statement'!F9 -> -0.0007920102 | G19: ='Income Statement'!G21/'Income Statement'!G9 -> -0.00029194476 | H19: =AVERAGE(C19:G19) -> -0.00059428014 | I19: =H19 -> -0.00059428014 | J19: =I19 -> -0.00059428014 | K19: =J19 -> -0.00059428014 | L19: =K19 -> -0.00059428014 | M19: =L19 -> -0.00059428014 | N19: =M19 -> -0.00059428014 | O19: =N19 -> -0.00059428014 | P19: =O19 -> -0.00059428014 | Q19: =P19 -> -0.00059428014
B20: Inventories days | C20: =('Balance Sheet'!D18/'Income Statement'!C10)*365 -> 377.89207 | D20: =('Balance Sheet'!E18/'Income Statement'!D10)*365 -> 317.23161 | E20: =('Balance Sheet'!F18/'Income Statement'!E10)*365 -> 359.89549 | F20: =('Balance Sheet'!G18/'Income Statement'!F10)*365 -> 337.80902 | G20: =('Balance Sheet'!H18/'Income Statement'!G10)*365 -> 347.88222 | H20: =AVERAGE(C20:G20) -> 348.14208 | I20: =H20 -> 348.14208 | J20: =I20 -> 348.14208 | K20: =J20 -> 348.14208 | L20: =K20 -> 348.14208 | M20: =L20 -> 348.14208 | N20: =M20 -> 348.14208 | O20: =N20 -> 348.14208 | P20: =O20 -> 348.14208 | Q20: =P20 -> 348.14208
B21: Trade receivables days | C21: =('Balance Sheet'!D20/'Income Statement'!C9)*365 -> 98.734169 | D21: =('Balance Sheet'!E20/'Income Statement'!D9)*365 -> 100.02473 | E21: =('Balance Sheet'!F20/'Income Statement'!E9)*365 -> 95.134817 | F21: =('Balance Sheet'!G20/'Income Statement'!F9)*365 -> 84.665706 | G21: =('Balance Sheet'!H20/'Income Statement'!G9)*365 -> 90.566212 | H21: =AVERAGE(C21:G21) -> 93.825126 | I21: =H21 -> 93.825126 | J21: =I21 -> 93.825126 | K21: =J21 -> 93.825126 | L21: =K21 -> 93.825126 | M21: =L21 -> 93.825126 | N21: =M21 -> 93.825126 | O21: =N21 -> 93.825126 | P21: =O21 -> 93.825126 | Q21: =P21 -> 93.825126
B22: Trade Payables days | C22: =('Balance Sheet'!D48/'Income Statement'!C10)*365 -> 166.90133 | D22: =('Balance Sheet'!E48/'Income Statement'!D10)*365 -> 157.94356 | E22: =('Balance Sheet'!F48/'Income Statement'!E10)*365 -> 194.49669 | F22: =('Balance Sheet'!G48/'Income Statement'!F10)*365 -> 193.52246 | G22: =('Balance Sheet'!H48/'Income Statement'!G10)*365 -> 210.0315 | H22: =AVERAGE(C22:G22) -> 184.57911 | I22: =H22 -> 184.57911 | J22: =I22 -> 184.57911 | K22: =J22 -> 184.57911 | L22: =K22 -> 184.57911 | M22: =L22 -> 184.57911 | N22: =M22 -> 184.57911 | O22: =N22 -> 184.57911 | P22: =O22 -> 184.57911 | Q22: =P22 -> 184.57911

Sheet Revenue Buildup
B7: Revenue Scenarios | C7: Growth (%) | E7: 46112 | F7: 46477 | G7: 46843 | H7: 47208 | I7: 47573 | J7: =I7+365 -> 47938 | K7: =J7+365 -> 48303 | L7: =K7+365 -> 48668 | M7: =L7+365 -> 49033 | N7: =M7+365 -> 49398
B8: Base Case | C8: ='Intro & Core Assumptions'!D30 -> 0.1 | E8: =C8 -> 0.1 | F8: =E8 -> 0.1 | G8: =F8 -> 0.1 | H8: =G8 -> 0.1 | I8: =H8 -> 0.1 | J8: =I8*(1-$C$11) -> 0.08325 | K8: =J8*(1-$C$11) -> 0.069305625 | L8: =K8*(1-$C$11) -> 0.057696933 | M8: =L8*(1-$C$11) -> 0.048032697 | N8: =M8*(1-$C$11) -> 0.03998722
B9: Bull Case | C9: 0.15 | E9: =C9 -> 0.15 | F9: =E9 -> 0.15 | G9: =F9 -> 0.15 | H9: =G9 -> 0.15 | I9: =H9 -> 0.15 | J9: =I9*(1-$C$11) -> 0.124875 | K9: =J9*(1-$C$11) -> 0.10395844 | L9: =K9*(1-$C$11) -> 0.086545399 | M9: =L9*(1-$C$11) -> 0.072049045 | N9: =M9*(1-$C$11) -> 0.05998083
B10: Worst Case | C10: 0.05 | E10: =C10 -> 0.05 | F10: =E10 -> 0.05 | G10: =F10 -> 0.05 | H10: =G10 -> 0.05 | I10: =H10 -> 0.05 | J10: =I10*(1-$C$11) -> 0.041625 | K10: =J10*(1-$C$11) -> 0.034652813 | L10: =K10*(1-$C$11) -> 0.028848466 | M10: =L10*(1-$C$11) -> 0.024016348 | N10: =M10*(1-$C$11) -> 0.01999361
B11: Tapering | C11: 0.1675

Sheet Historical
B6: (Source:Annual Report) | E6: (Amounts in ₹MM unless otherwise stated)
B7: STATEMENT OF PROFIT & LOSS
B8: Particulars | D8: 44286 | E8: 44651 | F8: 45016 | G8: 45382 | H8: 45747
B9: Income
B10: Revenue from operations | D10: 334981.4 | E10: 386544.9 | F10: 438856.8 | G10: 484968.5 | H10: 525784.4
B11: Other income | D11: 8355.2 | E11: 9215.1 | F11: 6345.2 | G11: 13541.9 | H11: 19650.4
B12: Total Income | D12: =SUM(D10:D11) -> 343336.6 | E12: =SUM(E10:E11) -> 395760 | F12: =SUM(F10:F11) -> 445202 | G12: =SUM(G10:G11) -> 498510.4 | H12: =SUM(H10:H11) -> 545434.8
B13: Expenses
B14: Cost of materials consumed | D14: 61531.3 | E14: 70491.2 | F14: 77775.7 | G14: 69043.3 | H14: 64491
B15: Purchases of stock-in-trade | D15: 31751.7 | E15: 34100.3 | F15: 35715 | G15: 34661.5 | H15: 41479.5
B16: Changes in inventories | D16: -6382.2 | E16: -1076.1 | F16: -6869.1 | G16: 2921.3 | H16: 1503.1
B17: Employee benefits expense | D17: 68622.3 | E17: 73008.3 | F17: 82960.3 | G17: 94290.6 | H17: 99731.2
B18: Finance costs | D18: 1414.3 | E18: 1273.5 | F18: 1720 | G18: 2384.7 | H18: 2313.6
B19: Depreciation & amortisation | D19: 20799.5 | E19: 21437.4 | F19: 25294.3 | G19: 25566.4 | H19: 25753.9
B20: Other expenses | D20: 94781.1 | E20: 107583.6 | F20: 131546 | G20: 154181.8 | H20: 167718
B21: Net (gain)/loss on forex | D21: -236.5 | E21: -1539.6 | F21: 1261 | G21: -361.3 | H21: -1855.3
B22: Total Expenses | D22: =SUM(D14:D21) -> 272281.5 | E22: =SUM(E14:E21) -> 305278.6 | F22: =SUM(F14:F21) -> 349403.2 | G22: =SUM(G14:G21) -> 382688.3 | H22: =SUM(H14:H21) -> 401135
B23: Profit before exceptional items & tax | D23: =D12-D22 -> 71055.1 | E23: =E12-E22 -> 90481.4 | F23: =F12-F22 -> 95798.8 | G23: =G12-G22 -> 115822.1 | H23: =H12-H22 -> 144299.8
B24: Exceptional items | D24: 43061.4 | E24: 45668.2 | F24: 1714.5 | G24: 4943.2 | H24: 6778.5
B25: Profit before tax (PBT) | D25: =D23-D24 -> 27993.7 | E25: =E23-E24 -> 44813.2 | F25: =F23-F24 -> 94084.3 | G25: =G23-G24 -> 110878.9 | H25: =H23-H24 -> 137521.3
B26: Tax Expense
B27: Current tax | D27: 9573 | E27: 3543.9 | F27: 18692.2 | G27: 19893 | H27: 33200.5
B28: Deferred tax | D28: -331 | E28: 7975.3 | F28: -10216.3 | G28: -5498.5 | H28: -9255
B29: Deferred tax (exceptional) | D29: -4095.1 | E29: -764.2 | F29: - | G29: - | H29: 3774.8
B30: Total Tax Expense | D30: =SUM(D27:D29) -> 5146.9 | E30: =SUM(E27:E29) -> 10755 | F30: =SUM(F27:F29) -> 8475.9 | G30: =SUM(G27:G29) -> 14394.5 | H30: =SUM(H27:H29) -> 27720.3
B31: Share of (loss)/gain of associates or JV | D31: -123.3 | E31: -165.4 | F31: -479 | G31: -384.1 | H31: -153.5
B32: Profit for the year | D32: =D25-D30+D31 -> 22723.5 | E32: =E25-E30+E31 -> 33892.8 | F32: =F25-F30+F31 -> 85129.4 | G32: =G25-G30+G31 -> 96100.3 | H32: =H25-H30+H31 -> 109647.5
B34: BALANCE SHEET
B35: Particulars | D35: 44286 | E35: 44651 | F35: 45016 | G35: 45382 | H35: 45747
B36: ASSETS
B37: Non-current assets
B38: Property, plant and equipment | D38: 102349.9 | E38: 103713.8 | F38: 103903.8 | G38: 101923.2 | H38: 100359.4
B39: Capital work-in-progress | D39: 9365.2 | E39: 7975.1 | F39: 9633.5 | G39: 11077.3 | H39: 12343.4
B40: Goodwill (Net) | D40: 62876.4 | E40: 65494.5 | F40: 87127.1 | G40: 85689.9 | H40: 89394.2
B41: Other intangible assets | D41: 50303.5 | E41: 55389.1 | F41: 53170.3 | G41: 44868.4 | H41: 36109.2
B42: Intangible assets under development | D42: 6303.1 | E42: 4892.9 | F42: 40098.1 | G42: 42461.5 | H42: 54096.2
B43: Financial assets | D43: 65788.5 | E43: 53412.6 | F43: 56233.8 | G43: 65600.3 | H43: 48775.3
B44: Deferred tax assets (Net) | D44: 35564.4 | E44: 28967.2 | F44: 31642.4 | G44: 41036.5 | H44: 44075.5
B45: Income tax assets (Net) | D45: 34327.8 | E45: 25115.3 | F45: 23069.8 | G45: 22850.3 | H45: 4206.7
B46: Other non-current assets | D46: 5367.4 | E46: 2888.4 | F46: 3723.7 | G46: 4739.3 | H46: 5401.2
...

Sheet Schedules
N6: (Amounts in ₹MM unless otherwise stated)
B7: SUPPORTING SCHEDULES
C8: Historical | H8: Forecasting
B9: Particulars | C9: 44286 | D9: 44651 | E9: 45016 | F9: 45382 | G9: 45747 | H9: 46112 | I9: 46477 | J9: 46843 | K9: 47208 | L9: 47573 | M9: =L9+365 -> 47938 | N9: =M9+365 -> 48303 | O9: =N9+365 -> 48668 | P9: =O9+365 -> 49033 | Q9: =P9+365 -> 49398
B10: Change in Working Capital
B11: Trade Receivables | C11: =CFS!D17 -> 937.3 | D11: =CFS!E17 -> -13422.6 | E11: =CFS!F17 -> -9531.7 | F11: =CFS!G17 -> 3528.9 | G11: =CFS!H17 -> -16020.5 | H11: ='Balance Sheet'!H20-'Balance Sheet'!I20 -> -18210.041 | I11: ='Balance Sheet'!I20-'Balance Sheet'!J20 -> -14867.114 | J11: ='Balance Sheet'!J20-'Balance Sheet'!K20 -> -16353.826 | K11: ='Balance Sheet'!K20-'Balance Sheet'!L20 -> -17989.208 | L11: ='Balance Sheet'!L20-'Balance Sheet'!M20 -> -19788.129 | M11: ='Balance Sheet'!M20-'Balance Sheet'!N20 -> -18120.979 | N11: ='Balance Sheet'!N20-'Balance Sheet'!O20 -> -16341.601 | O11: ='Balance Sheet'!O20-'Balance Sheet'!P20 -> -14547.243 | ... Q11: ='Balance Sheet'!Q20-'Balance Sheet'!R20 -> -11175.971
B12: Inventories | C12: =CFS!D16 -> -10802.9 | D12: =CFS!E16 -> 3069.5 | E12: =CFS!F16 -> -12022 | F12: =CFS!G16 -> 5988.1 | G12: =CFS!H16 -> -1839.7 | H12: ='Balance Sheet'!H18-'Balance Sheet'!I18 -> -29349.118 | I12: ='Balance Sheet'!I18-'Balance Sheet'!J18 -> -13178.242 | J12: ='Balance Sheet'!J18-'Balance Sheet'!K18 -> -14496.066 | K12: ='Balance Sheet'!K18-'Balance Sheet'!L18 -> -15945.673 | L12: ='Balance Sheet'!L18-'Balance Sheet'!M18 -> -17540.24 | M12: ='Balance Sheet'!M18-'Balance Sheet'!N18 -> -16062.475 | N12: ='Balance Sheet'!N18-'Balance Sheet'!O18 -> -14485.23 | O12: ='Balance Sheet'!O18-'Balance Sheet'!P18 -> -12894.707 | ... Q12: ='Balance Sheet'!Q18-'Balance Sheet'!R18 -> -9906.4044
B13: Trade Payables | C13: =CFS!D19 -> 3814.6 | D13: =CFS!E19 -> 3699.2 | E13: =CFS!F19 -> 11823.7 | F13: =CFS!G19 -> 2497.2 | G13: =CFS!H19 -> 5279.7 | H13: ='Balance Sheet'!I48-'Balance Sheet'!H48 -> 8025.4336 | I13: ='Balance Sheet'!J48-'Balance Sheet'!I48 -> 6986.8834 | J13: ='Balance Sheet'!K48-'Balance Sheet'!J48 -> 7685.5717 | K13: ='Balance Sheet'!L48-'Balance Sheet'!K48 -> 8454.1289 | L13: ='Balance Sheet'!M48-'Balance Sheet'!L48 -> 9299.5418 | M13: ='Balance Sheet'!N48-'Balance Sheet'!M48 -> 8516.0554 | N13: ='Balance Sheet'!O48-'Balance Sheet'!N48 -> 7679.8266 | O13: ='Balance Sheet'!P48-'Balance Sheet'!O48 -> 6836.5581 | ... Q13: ='Balance Sheet'!R48-'Balance Sheet'!Q48 -> 5252.2099
B14: Others | C14: =CFS!D18+CFS!D20+CFS!D21 -> 31691.9 | D14: =CFS!E18+CFS!E20+CFS!E21 -> 22244.4 | E14: =CFS!F18+CFS!F20+CFS!F21 -> -46888.2 | F14: =CFS!G18+CFS!G20+CFS!G21 -> -1392.9 | G14: =CFS!H18+CFS!H20+CFS!H21 -> 9344.9 | H14: 0 | I14: 0 | J14: 0 | K14: 0 | L14: 0 | M14: 0 | N14: 0 | O14: 0 | P14: 0 | Q14: 0
B15: Total | C15: =SUM(C11:C14) -> 25640.9 | D15: =SUM(D11:D14) -> 15590.5 | E15: =SUM(E11:E14) -> -56618.2 | F15: =SUM(F11:F14) -> 10621.3 | G15: =SUM(G11:G14) -> -3235.6 | H15: =SUM(H11:H14) -> -39533.726 | I15: =SUM(I11:I14) -> -21058.473 | J15: =SUM(J11:J14) -> -23164.32 | ... Q15: =SUM(Q11:Q14) -> -15830.165
B17: Depreciation
B18: PPE Opening | C18: =C21+C20 -> 123149.4 | D18: =C21 -> 102349.9 | E18: =D21 -> 103713.8 | F18: =E21 -> 103903.8 | G18: =F21 -> 101923.2 | H18: =G21 -> 100359.4 | I18: =H21 -> 98762.428 | J18: =I21 -> 97693.089 | K18: =J21 -> 96768.011 | ... Q18: =P21 -> 94581.018
B19: Add: Capex | C19: 0 | D19: =D21-D18+D20 -> 22801.3 | E19: =E21-E18+E20 -> 25484.3 | F19: =F21-F18+F20 -> 23585.8 | G19: =G21-G18+G20 -> 24190.1 | H19: =AVERAGE(D19:G19) -> 24015.375 | I19: =H19*(1+0.005) -> 24135.452 | J19: =I19*(1+0.005) -> 24256.129 | K19: =J19*(1+0.005) -> 24377.41 | L19: =K19*(1+0.005) -> 24499.297 | M19: =L19*(1+0.005) -> 24621.793 | N19: =M19*(1+0.005) -> 24744.902 | O19: =N19*(1+0.005) -> 24868.627 | P19: =O19*(1+0.005) -> 24992.97 | Q19: =P19*(1+0.005) -> 25117.935
B20: Less: Depreciation | C20: ='Income Statement'!C15 -> 20799.5 | D20: ='Income Statement'!D15 -> 21437.4 | E20: ='Income Statement'!E15 -> 25294.3 | F20: ='Income Statement'!F15 -> 25566.4 | G20: ='Income Statement'!G15 -> 25753.9 | H20: =H18*Assumptions!H14 -> 25612.347 | I20: =I18*Assumptions!I14 -> 25204.79 | J20: =J18*Assumptions!J14 -> 25181.207 | K20: =K18*Assumptions!K14 -> 24942.761 | L20: =L18*Assumptions!L14 -> 25045.007 | M20: =M18*Assumptions!M14 -> 24902.939 | N20: =N18*Assumptions!N14 -> 25078.044 | O20: =O18*Assumptions!O14 -> 24990.448 | ... Q20: =Q18*Assumptions!Q14 -> 25242.1
B21: PPE Closing | C21: ='Balance Sheet'!D11 -> 102349.9 | D21: ='Balance Sheet'!E11 -> 103713.8 | E21: ='Balance Sheet'!F11 -> 103903.8 | F21: ='Balance Sheet'!G11 -> 101923.2 | G21: ='Balance Sheet'!H11 -> 100359.4 | H21: =H18+H19-H20 -> 98762.428 | I21: =I18+I19-I20 -> 97693.089 | J21: =J18+J19-J20 -> 96768.011 | K21: =K18+K19-K20 -> 96202.661 | L21: =L18+L19-L20 -> 95656.95 | M21: =M18+M19-M20 -> 95375.804 | N21: =N18+N19-N20 -> 95042.663 | O21: =O18+O19-O20 -> 94920.841 | ... Q21: =Q18+Q19-Q20 -> 94456.853
B23: Debt & Interest Schedule
B24: Opening | C24: 33430.4 | D24: =C26 -> 35234.8 | E24: =D26 -> 9306.9 | F24: =E26 -> 61978.8 | G24: =F26 -> 28456.9 | H24: =G26 -> 18696.3 | I24: =H26 -> 18696.3 | J24: =I26 -> 18696.3 | K24: =J26 -> 18696.3 | ... Q24: =P26 -> 18696.3
B25: Issuance (repayment) | C25: =C26-C24 -> 1804.4 | D25: =D26-D24 -> -25927.9 | E25: =E26-E24 -> 52671.9 | F25: =F26-F24 -> -33521.9 | G25: =G26-G24 -> -9760.6 | H25: 0 | I25: 0 | J25: 0 | K25: 0 | L25: 0 | M25: 0 | N25: 0 | O25: 0 | P25: 0 | Q25: 0
B26: Closing | C26: ='Balance Sheet'!D38+'Balance Sheet'!D46 -> 35234.8 | D26: ='Balance Sheet'!E38+'Balance Sheet'!E46 -> 9306.9 | E26: ='Balance Sheet'!F38+'Balance Sheet'!F46 -> 61978.8 | F26: ='Balance Sheet'!G38+'Balance Sheet'!G46 -> 28456.9 | G26: ='Balance Sheet'!H38+'Balance Sheet'!H46 -> 18696.3 | H26: =H24+H25 -> 18696.3 | I26: =I24+I25 -> 18696.3 | J26: =J24+J25 -> 18696.3 | K26: =K24+K25 -> 18696.3 | L26: =L24+L25 -> 18696.3 | M26: =M24+M25 -> 18696.3 | N26: =N24+N25 -> 18696.3 | O26: =O24+O25 -> 18696.3 | ... Q26: =Q24+Q25 -> 18696.3
B27: Interest Expenses | C27: ='Income Statement'!C17 -> 1414.3 | D27: ='Income Statement'!D17 -> 1273.5 | E27: ='Income Statement'!E17 -> 1720 | F27: ='Income Statement'!F17 -> 2384.7 | G27: ='Income Statement'!G17 -> 2313.6 | H27: =H24*Assumptions!H15 -> 1520.0447 | I27: =I24*Assumptions!I15 -> 1520.0447 | J27: =J24*Assumptions!J15 -> 1520.0447 | K27: =K24*Assumptions!K15 -> 1520.0447 | L27: =L24*Assumptions!L15 -> 1520.0447 | M27: =M24*Assumptions!M15 -> 1520.0447 | N27: =N24*Assumptions!N15 -> 1520.0447 | O27: =O24*Assumptions!O15 -> 1520.0447 | ... Q27: =Q24*Assumptions!Q15 -> 1520.0447

Sheet Balance Sheet
O6: (Amounts in ₹MM unless otherwise stated)
D7: Historical | I7: Forecasting
B8: Particulars | D8: 44286 | E8: 44651 | F8: 45016 | G8: 45382 | H8: 45747 | I8: 46112 | J8: 46477 | K8: 46843 | L8: 47208 | M8: 47573 | N8: =M8+365 -> 47938 | O8: =N8+365 -> 48303 | P8: =O8+365 -> 48668 | Q8: =P8+365 -> 49033 | R8: =Q8+365 -> 49398
B9: ASSETS
B10: Non-current assets
B11: Property, plant and equipment | D11: =Historical!D38 -> 102349.9 | E11: =Historical!E38 -> 103713.8 | F11: =Historical!F38 -> 103903.8 | G11: =Historical!G38 -> 101923.2 | H11: =Historical!H38 -> 100359.4 | I11: =Schedules!H21 -> 98762.428 | J11: =Schedules!I21 -> 97693.089 | K11: =Schedules!J21 -> 96768.011 | L11: =Schedules!K21 -> 96202.661 | M11: =Schedules!L21 -> 95656.95 | N11: =Schedules!M21 -> 95375.804 | O11: =Schedules!N21 -> 95042.663 | P11: =Schedules!O21 -> 94920.841 | ... R11: =Schedules!Q21 -> 94456.853
B12: Capital work-in-progress | D12: =Historical!D39 -> 9365.2 | E12: =Historical!E39 -> 7975.1 | F12: =Historical!F39 -> 9633.5 | G12: =Historical!G39 -> 11077.3 | H12: =Historical!H39 -> 12343.4 | I12: =H12 -> 12343.4 | J12: =I12 -> 12343.4 | K12: =J12 -> 12343.4 | L12: =K12 -> 12343.4 | M12: =L12 -> 12343.4 | N12: =M12 -> 12343.4 | O12: =N12 -> 12343.4 | P12: =O12 -> 12343.4 | ... R12: =Q12 -> 12343.4
B13: Goodwill (Net) | D13: =Historical!D40 -> 62876.4 | E13: =Historical!E40 -> 65494.5 | F13: =Historical!F40 -> 87127.1 | G13: =Historical!G40 -> 85689.9 | H13: =Historical!H40 -> 89394.2 | I13: =H13 -> 89394.2 | J13: =I13 -> 89394.2 | K13: =J13 -> 89394.2 | L13: =K13 -> 89394.2 | M13: =L13 -> 89394.2 | N13: =M13 -> 89394.2 | O13: =N13 -> 89394.2 | P13: =O13 -> 89394.2 | ... R13: =Q13 -> 89394.2
B14: Financial assets | D14: =Historical!D43 -> 65788.5 | E14: =Historical!E43 -> 53412.6 | F14: =Historical!F43 -> 56233.8 | G14: =Historical!G43 -> 65600.3 | H14: =Historical!H43 -> 48775.3 | I14: =H14 -> 48775.3 | J14: =I14 -> 48775.3 | K14: =J14 -> 48775.3 | L14: =K14 -> 48775.3 | M14: =L14 -> 48775.3 | N14: =M14 -> 48775.3 | O14: =N14 -> 48775.3 | P14: =O14 -> 48775.3 | ... R14: =Q14 -> 48775.3
B15: Other non-current assets | D15: =Historical!D41+Historical!D42+Historical!D44+Historical!D45+Historical!D46 -> 131866.2 | E15: =Historical!E41+Historical!E42+Historical!E44+Historical!E45+Historical!E46 -> 117252.9 | F15: =Historical!F41+Historical!F42+Historical!F44+Historical!F45+Historical!F46 -> 151704.3 | G15: =Historical!G41+Historical!G42+Historical!G44+Historical!G45+Historical!G46 -> 155956 | H15: =Historical!H41+Historical!H42+Historical!H44+Historical!H45+Historical!H46 -> 143888.8 | I15: =H15 -> 143888.8 | J15: =I15 -> 143888.8 | K15: =J15 -> 143888.8 | L15: =K15 -> 143888.8 | M15: =L15 -> 143888.8 | N15: =M15 -> 143888.8 | O15: =N15 -> 143888.8 | P15: =O15 -> 143888.8 | ... R15: =Q15 -> 143888.8
B16: Total non-current assets | D16: =SUM(D11:D15) -> 372246.2 | E16: =SUM(E11:E15) -> 347848.9 | F16: =SUM(F11:F15) -> 408602.5 | G16: =SUM(G11:G15) -> 420246.7 | H16: =SUM(H11:H15) -> 394761.1 | I16: =SUM(I11:I15) -> 393164.13 | J16: =SUM(J11:J15) -> 392094.79 | K16: =SUM(K11:K15) -> 391169.71 | ... R16: =SUM(R11:R15) -> 388858.55
B17: Current assets
B18: Inventories | D18: =Historical!D49 -> 89970.2 | E18: =Historical!E49 -> 89968.1 | F18: =Historical!F49 -> 105130.5 | G18: =Historical!G49 -> 98682.9 | H18: =Historical!H49 -> 102433.3 | I18: =('Income Statement'!H10*Assumptions!H20)/365 -> 131782.42 | J18: =('Income Statement'!I10*Assumptions!I20)/365 -> 144960.66 | K18: =('Income Statement'!J10*Assumptions!J20)/365 -> 159456.73 | L18: =('Income Statement'!K10*Assumptions!K20)/365 -> 175402.4 | M18: =('Income Statement'!L10*Assumptions!L20)/365 -> 192942.64 | N18: =('Income Statement'!M10*Assumptions!M20)/365 -> 209005.11 | O18: =('Income Statement'!N10*Assumptions!N20)/365 -> 223490.34 | P18: =('Income Statement'!O10*Assumptions!O20)/365 -> 236385.05 | ... R18: =('Income Statement'!Q10*Assumptions!Q20)/365 -> 257645.67
B19: Investments | D19: =Historical!D50 -> 31300.6 | E19: =Historical!E50 -> 76339.4 | F19: =Historical!F50 -> 93726.1 | G19: =Historical!G50 -> 85845.4 | H19: =Historical!H50 -> 136561 | I19: =H19 -> 136561 | J19: =I19 -> 136561 | K19: =J19 -> 136561 | L19: =K19 -> 136561 | M19: =L19 -> 136561 | N19: =M19 -> 136561 | O19: =N19 -> 136561 | P19: =O19 -> 136561 | ... R19: =Q19 -> 136561
B20: Trade receivables | D20: =Historical!D51 -> 90614 | E20: =Historical!E51 -> 105928.9 | F20: =Historical!F51 -> 114385.1 | G20: =Historical!G51 -> 112493.7 | H20: =Historical!H51 -> 130461.1 | I20: =('Income Statement'!H9*Assumptions!H21)/365 -> 148671.14 | J20: =('Income Statement'!I9*Assumptions!I21)/365 -> 163538.26 | K20: =('Income Statement'!J9*Assumptions!J21)/365 -> 179892.08 | L20: =('Income Statement'!K9*Assumptions!K21)/365 -> 197881.29 | M20: =('Income Statement'!L9*Assumptions!L21)/365 -> 217669.42 | N20: =('Income Statement'!M9*Assumptions!M21)/365 -> 235790.4 | O20: =('Income Statement'!N9*Assumptions!N21)/365 -> 252132 | P20: =('Income Statement'!O9*Assumptions!O21)/365 -> 266679.24 | ... R20: =('Income Statement'!Q9*Assumptions!Q21)/365 -> 290664.53
B21: Cash and cash equivalents | D21: =Historical!D52 -> 62730.3 | E21: =Historical!E52 -> 45082.5 | F21: =Historical!F52 -> 46237.3 | G21: =Historical!G52 -> 92856.5 | H21: =Historical!H52 -> 102687.7 | I21: =CFS!I45 -> 140651.23 | J21: =CFS!J45 -> 205869.13 | K21: =CFS!K45 -> 278596.68 | L21: =CFS!L45 -> 359740.75 | M21: =CFS!M45 -> 450012.52 | N21: =CFS!N45 -> 553472.37 | O21: =CFS!O45 -> 668976.23 | P21: =CFS!P45 -> 795676.4 | ... R21: =CFS!R45 -> 1077671.7
B22: Bank balances (other than above) | D22: =Historical!D53 -> 1724.8 | E22: =Historical!E53 -> 5251 | F22: =Historical!F53 -> 11465.6 | G22: =Historical!G53 -> 12350.3 | H22: =Historical!H53 -> 10628.5 | I22: =H22 -> 10628.5 | J22: =I22 -> 10628.5 | K22: =J22 -> 10628.5 | L22: =K22 -> 10628.5 | M22: =L22 -> 10628.5 | N22: =M22 -> 10628.5 | O22: =N22 -> 10628.5 | P22: =O22 -> 10628.5 | ... R22: =Q22 -> 10628.5
B23: Loans & Advances | D23: =Historical!D54 -> 560.1 | E23: =Historical!E54 -> 1699.7 | F23: =Historical!F54 -> 413.2 | G23: =Historical!G54 -> 650.2 | H23: =Historical!H54 -> 483.8 | I23: =H23 -> 483.8 | J23: =I23 -> 483.8 | K23: =J23 -> 483.8 | L23: =K23 -> 483.8 | M23: =L23 -> 483.8 | N23: =M23 -> 483.8 | O23: =N23 -> 483.8 | P23: =O23 -> 483.8 | ... R23: =Q23 -> 483.8
B24: Other financial assets | D24: =Historical!D55 -> 8759.3 | E24: =Historical!E55 -> 7024.7 | F24: =Historical!F55 -> 7645.1 | G24: =Historical!G55 -> 9172 | H24: =Historical!H55 -> 17406.6 | I24: =H24 -> 17406.6 | J24: =I24 -> 17406.6 | K24: =J24 -> 17406.6 | L24: =K24 -> 17406.6 | M24: =L24 -> 17406.6 | N24: =M24 -> 17406.6 | O24: =N24 -> 17406.6 | P24: =O24 -> 17406.6 | ... R24: =Q24 -> 17406.6
B25: Other current assets | D25: =Historical!D56 -> 18761.5 | E25: =Historical!E56 -> 18855.5 | F25: =Historical!F56 -> 19616.5 | G25: =Historical!G56 -> 22280.1 | H25: =Historical!H56 -> 25278.6 | I25: =H25 -> 25278.6 | J25: =I25 -> 25278.6 | K25: =J25 -> 25278.6 | L25: =K25 -> 25278.6 | M25: =L25 -> 25278.6 | N25: =M25 -> 25278.6 | O25: =N25 -> 25278.6 | P25: =O25 -> 25278.6 | ... R25: =Q25 -> 25278.6
B26: Total current assets | D26: =SUM(D18:D25) -> 304420.8 | E26: =SUM(E18:E25) -> 350149.8 | F26: =SUM(F18:F25) -> 398619.4 | G26: =SUM(G18:G25) -> 434331.1 | H26: =SUM(H18:H25) -> 525940.6 | I26: =SUM(I18:I25) -> 611463.29 | J26: =SUM(J18:J25) -> 704726.54 | K26: =SUM(K18:K25) -> 808303.99 | ... R26: =SUM(R18:R25) -> 1816340.4
B27: Assets classified as held for sale | D27: =Historical!D58 -> 0 | E27: =Historical!E58 -> 0 | F27: =Historical!F58 -> 214 | G27: =Historical!G58 -> 418.7 | H27: =Historical!H58 -> 304.1 | I27: =H27-0.1 -> 304 | J27: =I27 -> 304 | K27: =J27 -> 304 | L27: =K27 -> 304 | M27: =L27 -> 304 | N27: =M27 -> 304 | O27: =N27 -> 304 | P27: =O27 -> 304 | Q27: =P27 -> 304 | R27: =Q27 -> 304
B28: TOTAL ASSETS | D28: =D26+D16+D27 -> 676667 | E28: =E26+E16+E27 -> 697998.7 | F28: =F26+F16+F27 -> 807435.9 | G28: =G26+G16+G27 -> 854996.5 | H28: =H26+H16+H27 -> 921005.8 | I28: =I26+I16+I27 -> 1004931.4 | J28: =J26+J16+J27 -> 1097125.3 | K28: =K26+K16+K27 -> 1199777.7 | ... R28: =R26+R16+R27 -> 2205503
B30: EQUITY & LIABILITIES
B31: Equity
B32: Equity share capital | D32: =Historical!D62 -> 2399.3 | E32: =Historical!E62 -> 2399.3 | F32: =Historical!F62 -> 2399.3 | G32: =Historical!G62 -> 2399.3 | H32: =Historical!H62 -> 2399.3 | I32: =H32 -> 2399.3 | J32: =I32 -> 2399.3 | K32: =J32 -> 2399.3 | L32: =K32 -> 2399.3 | M32: =L32 -> 2399.3 | N32: =M32 -> 2399.3 | O32: =N32 -> 2399.3 | P32: =O32 -> 2399.3 | ... R32: =Q32 -> 2399.3
B33: Reserves | D33: =Historical!D63 -> 462228.5 | E33: =Historical!E63 -> 477712.9 | F33: =Historical!F63 -> 557554.5 | G33: =Historical!G63 -> 634268.2 | H33: =Historical!H63 -> 719780.9 | I33: =H33+('Income Statement'!H22*(1-Assumptions!H16)) -> 795681.08 | J33: =I33+('Income Statement'!I22*(1-Assumptions!I16)) -> 880888.12 | K33: =J33+('Income Statement'!J22*(1-Assumptions!J16)) -> 975854.91 | L33: =K33+('Income Statement'!K22*(1-Assumptions!K16)) -> 1081914.4 | M33: =L33+('Income Statement'!L22*(1-Assumptions!L16)) -> 1199669.3 | N33: =M33+('Income Statement'!M22*(1-Assumptions!M16)) -> 1328515.4 | O33: =N33+('Income Statement'!N22*(1-Assumptions!N16)) -> 1466833.1 | P33: =O33+('Income Statement'!O22*(1-Assumptions!O16)) -> 1614016.8 | ... R33: =Q33+('Income Statement'!Q22*(1-Assumptions!Q16)) -> 1929522
B34: Non-controlling interests | D34: =Historical!D64 -> 30170.5 | E34: =Historical!E64 -> 30548.9 | F34: =Historical!F64 -> 33200.9 | G34: =Historical!G64 -> 34591.9 | H34: =Historical!H64 -> 2679.3 | I34: =H34 -> 2679.3 | J34: =I34 -> 2679.3 | K34: =J34 -> 2679.3 | L34: =K34 -> 2679.3 | M34: =L34 -> 2679.3 | N34: =M34 -> 2679.3 | O34: =N34 -> 2679.3 | P34: =O34 -> 2679.3 | ... R34: =Q34 -> 2679.3
B35: Total Equity | D35: =SUM(D32:D34) -> 494798.3 | E35: =SUM(E32:E34) -> 510661.1 | F35: =SUM(F32:F34) -> 593154.7 | G35: =SUM(G32:G34) -> 671259.4 | H35: =SUM(H32:H34) -> 724859.5 | I35: =SUM(I32:I34) -> 800759.68 | J35: =SUM(J32:J34) -> 885966.72 | K35: =SUM(K32:K34) -> 980933.51 | ... R35: =SUM(R32:R34) -> 1934600.6
B36: Liabilities
B37: Non-current liabilities
B38: Borrowings | D38: =Historical!D68 -> 6547 | E38: =Historical!E68 -> 2299.2 | F38: =Historical!F68 -> 0 | G38: =Historical!G68 -> 13.3 | H38: =Historical!H68 -> 25.2 | I38: =H38 -> 25.2 | J38: =I38 -> 25.2 | K38: =J38 -> 25.2 | L38: =K38 -> 25.2 | M38: =L38 -> 25.2 | N38: =M38 -> 25.2 | O38: =N38 -> 25.2 | P38: =O38 -> 25.2 | ... R38: =Q38 -> 25.2
B39: Lease liabilities | D39: =Historical!D69 -> 2434 | E39: =Historical!E69 -> 2517.9 | F39: =Historical!F69 -> 5599.1 | G39: =Historical!G69 -> 3022.9 | H39: =Historical!H69 -> 3557.4 | I39: =H39 -> 3557.4 | J39: =I39 -> 3557.4 | K39: =J39 -> 3557.4 | L39: =K39 -> 3557.4 | M39: =L39 -> 3557.4 | N39: =M39 -> 3557.4 | O39: =N39 -> 3557.4 | P39: =O39 -> 3557.4 | ... R39: =Q39 -> 3557.4
B40: Provisions | D40: =Historical!D70 -> 3271.2 | E40: =Historical!E70 -> 3690.7 | F40: =Historical!F70 -> 3429.1 | G40: =Historical!G70 -> 4138.9 | H40: =Historical!H70 -> 4650.4 | I40: =H40 -> 4650.4 | J40: =I40 -> 4650.4 | K40: =J40 -> 4650.4 | L40: =K40 -> 4650.4 | M40: =L40 -> 4650.4 | N40: =M40 -> 4650.4 | O40: =N40 -> 4650.4 | P40: =O40 -> 4650.4 | ... R40: =Q40 -> 4650.4
B41: Deferred tax liabilities (Net) | D41: =Historical!D71 -> 445.1 | E41: =Historical!E71 -> 318.6 | F41: =Historical!F71 -> 316.9 | G41: =Historical!G71 -> 1718.6 | H41: =Historical!H71 -> 1924.4 | I41: =H41 -> 1924.4 | J41: =I41 -> 1924.4 | K41: =J41 -> 1924.4 | L41: =K41 -> 1924.4 | M41: =L41 -> 1924.4 | N41: =M41 -> 1924.4 | O41: =N41 -> 1924.4 | P41: =O41 -> 1924.4 | ... R41: =Q41 -> 1924.4
B42: Other non-current liabilities | D42: =Historical!D72 -> 7715.1 | E42: =Historical!E72 -> 6505.7 | F42: =Historical!F72 -> 5866.1 | G42: =Historical!G72 -> 4999.4 | H42: =Historical!H72 -> 3959.2 | I42: =H42 -> 3959.2 | J42: =I42 -> 3959.2 | K42: =J42 -> 3959.2 | L42: =K42 -> 3959.2 | M42: =L42 -> 3959.2 | N42: =M42 -> 3959.2 | O42: =N42 -> 3959.2 | P42: =O42 -> 3959.2 | ... R42: =Q42 -> 3959.2
B43: Non-current tax liabilities | D43: =Historical!D73 -> - | E43: =Historical!E73 -> - | F43: =Historical!F73 -> - | G43: =Historical!G73 -> - | H43: =Historical!H73 -> 87.6 | I43: =H43 -> 87.6 | J43: =I43 -> 87.6 | K43: =J43 -> 87.6 | L43: =K43 -> 87.6 | M43: =L43 -> 87.6 | N43: =M43 -> 87.6 | O43: =N43 -> 87.6 | P43: =O43 -> 87.6 | ... R43: =Q43 -> 87.6
B44: Total non-current liabilities | D44: =SUM(D38:D43) -> 20412.4 | E44: =SUM(E38:E43) -> 15332.1 | F44: =SUM(F38:F43) -> 15211.2 | G44: =SUM(G38:G43) -> 13893.1 | H44: =SUM(H38:H43) -> 14204.2 | I44: =SUM(I38:I43) -> 14204.2 | J44: =SUM(J38:J43) -> 14204.2 | K44: =SUM(K38:K43) -> 14204.2 | ... R44: =SUM(R38:R43) -> 14204.2
B45: Current liabilities
B46: Borrowings | D46: =Historical!D76 -> 28687.8 | E46: =Historical!E76 -> 7007.7 | F46: =Historical!F76 -> 61978.8 | G46: =Historical!G76 -> 28443.6 | H46: =Historical!H76 -> 18671.1 | I46: =H46 -> 18671.1 | J46: =I46 -> 18671.1 | K46: =J46 -> 18671.1 | L46: =K46 -> 18671.1 | M46: =L46 -> 18671.1 | N46: =M46 -> 18671.1 | O46: =N46 -> 18671.1 | P46: =O46 -> 18671.1 | ... R46: =Q46 -> 18671.1
...

Sheet Income Statement
N6: (Amounts in ₹MM unless otherwise stated)
C7: Historical | H7: Forecasting
B8: Particulars | C8: 44286 | D8: 44651 | E8: 45016 | F8: 45382 | G8: 45747 | H8: 46112 | I8: 46477 | J8: 46843 | K8: 47208 | L8: 47573 | M8: =L8+365 -> 47938 | N8: =M8+365 -> 48303 | O8: =N8+365 -> 48668 | P8: =O8+365 -> 49033 | Q8: =P8+365 -> 49398
B9: Sales | C9: =Historical!D10 -> 334981.4 | D9: =Historical!E10 -> 386544.9 | E9: =Historical!F10 -> 438856.8 | F9: =Historical!G10 -> 484968.5 | G9: =Historical!H10 -> 525784.4 | H9: =G9*(1+Assumptions!H10) -> 578362.84 | I9: =H9*(1+Assumptions!I10) -> 636199.12 | J9: =I9*(1+Assumptions!J10) -> 699819.04 | K9: =J9*(1+Assumptions!K10) -> 769800.94 | L9: =K9*(1+Assumptions!L10) -> 846781.03 | M9: =L9*(1+Assumptions!M10) -> 917275.56 | N9: =M9*(1+Assumptions!N10) -> 980847.91 | O9: =N9*(1+Assumptions!O10) -> 1037439.8 | ... Q9: =P9*(1+Assumptions!Q10) -> 1130747.8
B10: Less: COGS | C10: =Historical!D14+Historical!D15+Historical!D16 -> 86900.8 | D10: =Historical!E14+Historical!E15+Historical!E16 -> 103515.4 | E10: =Historical!F14+Historical!F15+Historical!F16 -> 106621.6 | F10: =Historical!G14+Historical!G15+Historical!G16 -> 106626.1 | G10: =Historical!H14+Historical!H15+Historical!H16 -> 107473.6 | H10: =H9*Assumptions!H11 -> 138163.66 | I10: =I9*Assumptions!I11 -> 151980.02 | J10: =J9*Assumptions!J11 -> 167178.02 | K10: =K9*Assumptions!K11 -> 183895.83 | L10: =L9*Assumptions!L11 -> 202285.41 | M10: =M9*Assumptions!M11 -> 219125.67 | N10: =N9*Assumptions!N11 -> 234312.31 | O10: =O9*Assumptions!O11 -> 247831.41 | ... Q10: =Q9*Assumptions!Q11 -> 270121.52
B11: Groos Profit | C11: =C9-C10 -> 248080.6 | D11: =D9-D10 -> 283029.5 | E11: =E9-E10 -> 332235.2 | F11: =F9-F10 -> 378342.4 | G11: =G9-G10 -> 418310.8 | H11: =H9-H10 -> 440199.18 | I11: =I9-I10 -> 484219.1 | J11: =J9-J10 -> 532641.01 | ... Q11: =Q9-Q10 -> 860626.28
B12: Less: Employee Cost | C12: =Historical!D17 -> 68622.3 | D12: =Historical!E17 -> 73008.3 | E12: =Historical!F17 -> 82960.3 | F12: =Historical!G17 -> 94290.6 | G12: =Historical!H17 -> 99731.2 | H12: ='Income Statement'!H9*Assumptions!H12 -> 111840.62 | I12: ='Income Statement'!I9*Assumptions!I12 -> 123024.68 | J12: ='Income Statement'!J9*Assumptions!J12 -> 135327.15 | K12: ='Income Statement'!K9*Assumptions!K12 -> 148859.86 | L12: ='Income Statement'!L9*Assumptions!L12 -> 163745.85 | M12: ='Income Statement'!M9*Assumptions!M12 -> 177377.69 | N12: ='Income Statement'!N9*Assumptions!N12 -> 189670.96 | O12: ='Income Statement'!O9*Assumptions!O12 -> 200614.39 | ... Q12: ='Income Statement'!Q9*Assumptions!Q12 -> 218657.77
B13: Less: Selling, admin and other expenses | C13: =Historical!D20 -> 94781.1 | D13: =Historical!E20 -> 107583.6 | E13: =Historical!F20 -> 131546 | F13: =Historical!G20 -> 154181.8 | G13: =Historical!H20 -> 167718 | H13: =H9*Assumptions!H13 -> 173268.25 | I13: =I9*Assumptions!I13 -> 190595.07 | J13: =J9*Assumptions!J13 -> 209654.58 | K13: =K9*Assumptions!K13 -> 230620.04 | L13: =L9*Assumptions!L13 -> 253682.04 | M13: =M9*Assumptions!M13 -> 274801.07 | N13: =N9*Assumptions!N13 -> 293846.33 | O13: =O9*Assumptions!O13 -> 310800.37 | ... Q13: =Q9*Assumptions!Q13 -> 338753.94
B14: EBITDA | C14: =C11-C12-C13 -> 84677.2 | D14: =D11-D12-D13 -> 102437.6 | E14: =E11-E12-E13 -> 117728.9 | F14: =F11-F12-F13 -> 129870 | G14: =G11-G12-G13 -> 150861.6 | H14: =H11-H12-H13 -> 155090.32 | I14: =I11-I12-I13 -> 170599.35 | J14: =J11-J12-J13 -> 187659.28 | ... Q14: =Q11-Q12-Q13 -> 303214.56
B15: Less: Depreciation & Ammotization | C15: =Historical!D19 -> 20799.5 | D15: =Historical!E19 -> 21437.4 | E15: =Historical!F19 -> 25294.3 | F15: =Historical!G19 -> 25566.4 | G15: =Historical!H19 -> 25753.9 | H15: =Schedules!H20 -> 25612.347 | I15: =Schedules!I20 -> 25204.79 | J15: =Schedules!J20 -> 25181.207 | K15: =Schedules!K20 -> 24942.761 | L15: =Schedules!L20 -> 25045.007 | M15: =Schedules!M20 -> 24902.939 | N15: =Schedules!N20 -> 25078.044 | O15: =Schedules!O20 -> 24990.448 | ... Q15: =Schedules!Q20 -> 25242.1
B16: EBIT | C16: =C14-C15 -> 63877.7 | D16: =D14-D15 -> 81000.2 | E16: =E14-E15 -> 92434.6 | F16: =F14-F15 -> 104303.6 | G16: =G14-G15 -> 125107.7 | H16: =H14-H15 -> 129477.97 | I16: =I14-I15 -> 145394.56 | J16: =J14-J15 -> 162478.08 | ... Q16: =Q14-Q15 -> 277972.46
B17: Less: Interest | C17: =Historical!D18 -> 1414.3 | D17: =Historical!E18 -> 1273.5 | E17: =Historical!F18 -> 1720 | F17: =Historical!G18 -> 2384.7 | G17: =Historical!H18 -> 2313.6 | H17: =Schedules!H27 -> 1520.0447 | I17: =Schedules!I27 -> 1520.0447 | J17: =Schedules!J27 -> 1520.0447 | K17: =Schedules!K27 -> 1520.0447 | L17: =Schedules!L27 -> 1520.0447 | M17: =Schedules!M27 -> 1520.0447 | N17: =Schedules!N27 -> 1520.0447 | O17: =Schedules!O27 -> 1520.0447 | ... Q17: =Schedules!Q27 -> 1520.0447
B18: Add: Other Income | C18: =Historical!D11-Historical!D21-Historical!D24 -> -34469.7 | D18: =Historical!E11-Historical!E21-Historical!E24 -> -34913.5 | E18: =Historical!F11-Historical!F21-Historical!F24 -> 3369.7 | F18: =Historical!G11-Historical!G21-Historical!G24 -> 8960 | G18: =Historical!H11-Historical!H21-Historical!H24 -> 14727.2 | H18: =H9*Assumptions!H17 -> 10442.099 | I18: =I9*Assumptions!I17 -> 11486.309 | J18: =J9*Assumptions!J17 -> 12634.94 | K18: =K9*Assumptions!K17 -> 13898.434 | L18: =L9*Assumptions!L17 -> 15288.278 | M18: =M9*Assumptions!M17 -> 16561.027 | N18: =N9*Assumptions!N17 -> 17708.799 | O18: =O9*Assumptions!O17 -> 18730.542 | ... Q18: =Q9*Assumptions!Q17 -> 20415.179
B19: Profit before tax | C19: =C16-C17+C18 -> 27993.7 | D19: =D16-D17+D18 -> 44813.2 | E19: =E16-E17+E18 -> 94084.3 | F19: =F16-F17+F18 -> 110878.9 | G19: =G16-G17+G18 -> 137521.3 | H19: =H16-H17+H18 -> 138400.02 | I19: =I16-I17+I18 -> 155360.82 | J19: =J16-J17+J18 -> 173592.97 | ... Q19: =Q16-Q17+Q18 -> 296867.6
B20: Less: Tax | C20: =Historical!D30 -> 5146.9 | D20: =Historical!E30 -> 10755 | E20: =Historical!F30 -> 8475.9 | F20: =Historical!G30 -> 14394.5 | G20: =Historical!H30 -> 27720.3 | H20: =H19*Assumptions!H18 -> 28176.4 | I20: =I19*Assumptions!I18 -> 31629.392 | J20: =J19*Assumptions!J18 -> 35694.627 | K20: =K19*Assumptions!K18 -> 39862.157 | L20: =L19*Assumptions!L18 -> 44815.199 | M20: =M19*Assumptions!M18 -> 49034.858 | N20: =N19*Assumptions!N18 -> 53304.97 | O20: =O19*Assumptions!O18 -> 56720.774 | ... Q20: =Q19*Assumptions!Q18 -> 62892.321
B21: Share of (loss)/gain of associates or JV | C21: =Historical!D31 -> -123.3 | D21: =Historical!E31 -> -165.4 | E21: =Historical!F31 -> -479 | F21: =Historical!G31 -> -384.1 | G21: =Historical!H31 -> -153.5 | H21: =H9*Assumptions!H19 -> -343.70955 | I21: =I9*Assumptions!I19 -> -378.0805 | J21: =J9*Assumptions!J19 -> -415.88855 | K21: =K9*Assumptions!K19 -> -457.47741 | L21: =L9*Assumptions!L19 -> -503.22515 | M21: =M9*Assumptions!M19 -> -545.11864 | N21: =N9*Assumptions!N19 -> -582.89843 | O21: =O9*Assumptions!O19 -> -616.52988 | ... Q21: =Q9*Assumptions!Q19 -> -671.98095
B22: Net profit | C22: =C19-C20+C21 -> 22723.5 | D22: =D19-D20+D21 -> 33892.8 | E22: =E19-E20+E21 -> 85129.4 | F22: =F19-F20+F21 -> 96100.3 | G22: =G19-G20+G21 -> 109647.5 | H22: =H19-H20+H21 -> 109879.92 | I22: =I19-I20+I21 -> 123353.35 | J22: =J19-J20+J21 -> 137482.46 | ... Q22: =Q19-Q20+Q21 -> 233303.29

Sheet CFS
O6: (Amounts in ₹MM unless otherwise stated)
D7: Historical | I7: Forecasting
B8: Particulars | D8: 44286 | E8: 44651 | F8: 45016 | G8: 45382 | H8: 45747 | I8: 46112 | J8: 46477 | K8: 46843 | L8: 47208 | M8: 47573 | N8: =M8+365 -> 47938 | O8: =N8+365 -> 48303 | P8: =O8+365 -> 48668 | Q8: =P8+365 -> 49033 | R8: =Q8+365 -> 49398
B9: =Historical!B91 -> A. Cash Flow from Operating Activities
B10: =Historical!B92 -> Profit before tax | D10: =Historical!D92 -> 27993.7 | E10: =Historical!E92 -> 44813.2 | F10: =Historical!F92 -> 94084.3 | G10: =Historical!G92 -> 110878.9 | H10: =Historical!H92 -> 137521.3 | I10: ='Income Statement'!H19 -> 138400.02 | J10: ='Income Statement'!I19 -> 155360.82 | K10: ='Income Statement'!J19 -> 173592.97 | L10: ='Income Statement'!K19 -> 193860.84 | M10: ='Income Statement'!L19 -> 215790.96 | N10: ='Income Statement'!M19 -> 236109.17 | O10: ='Income Statement'!N19 -> 254129.02 | P10: ='Income Statement'!O19 -> 270413.7 | ... R10: ='Income Statement'!Q19 -> 296867.6
B11: =Historical!B93 -> Depreciation & amortisation | D11: =Historical!D93 -> 20799.5 | E11: =Historical!E93 -> 21437.4 | F11: =Historical!F93 -> 25294.3 | G11: =Historical!G93 -> 25566.4 | H11: =Historical!H93 -> 25753.9 | I11: ='Income Statement'!H15 -> 25612.347 | J11: ='Income Statement'!I15 -> 25204.79 | K11: ='Income Statement'!J15 -> 25181.207 | L11: ='Income Statement'!K15 -> 24942.761 | M11: ='Income Statement'!L15 -> 25045.007 | N11: ='Income Statement'!M15 -> 24902.939 | O11: ='Income Statement'!N15 -> 25078.044 | P11: ='Income Statement'!O15 -> 24990.448 | ... R11: ='Income Statement'!Q15 -> 25242.1
B12: =Historical!B94 -> Finance costs | D12: =Historical!D94 -> 1414.3 | E12: =Historical!E94 -> 1273.5 | F12: =Historical!F94 -> 1720 | G12: =Historical!G94 -> 2384.7 | H12: =Historical!H94 -> 2313.6 | I12: ='Income Statement'!H17 -> 1520.0447 | J12: ='Income Statement'!I17 -> 1520.0447 | K12: ='Income Statement'!J17 -> 1520.0447 | L12: ='Income Statement'!K17 -> 1520.0447 | M12: ='Income Statement'!L17 -> 1520.0447 | N12: ='Income Statement'!M17 -> 1520.0447 | O12: ='Income Statement'!N17 -> 1520.0447 | P12: ='Income Statement'!O17 -> 1520.0447 | ... R12: ='Income Statement'!Q17 -> 1520.0447
B13: =Historical!B96 -> Other adjustments (net) | D13: =Historical!D95+Historical!D96 -> -4115.3 | E13: =Historical!E95+Historical!E96 -> -2961.4 | F13: =Historical!F95+Historical!F96 -> 211.3 | G13: =Historical!G95+Historical!G96 -> -12407.1 | H13: =Historical!H95+Historical!H96 -> -16863.9 | I13: =-'Income Statement'!H18+'Income Statement'!H21 -> -10785.809 | J13: =-'Income Statement'!I18+'Income Statement'!I21 -> -11864.39 | K13: =-'Income Statement'!J18+'Income Statement'!J21 -> -13050.829 | L13: =-'Income Statement'!K18+'Income Statement'!K21 -> -14355.911 | M13: =-'Income Statement'!L18+'Income Statement'!L21 -> -15791.503 | N13: =-'Income Statement'!M18+'Income Statement'!M21 -> -17106.145 | O13: =-'Income Statement'!N18+'Income Statement'!N21 -> -18291.697 | P13: =-'Income Statement'!O18+'Income Statement'!O21 -> -19347.072 | ... R13: =-'Income Statement'!Q18+'Income Statement'!Q21 -> -21087.16
B14: =Historical!B97 -> Operating profit before WC changes | D14: =SUM(D10:D13) -> 46092.2 | E14: =SUM(E10:E13) -> 64562.7 | F14: =SUM(F10:F13) -> 121309.9 | G14: =SUM(G10:G13) -> 126422.9 | H14: =SUM(H10:H13) -> 148724.9 | I14: =SUM(I10:I13) -> 154746.61 | J14: =SUM(J10:J13) -> 170221.27 | K14: =SUM(K10:K13) -> 187243.4 | ... R14: =SUM(R10:R13) -> 302542.58
B15: =Historical!B98 -> Working Capital Changes
B16: =Historical!B99 -> Inventories | D16: =Historical!D99 -> -10802.9 | E16: =Historical!E99 -> 3069.5 | F16: =Historical!F99 -> -12022 | G16: =Historical!G99 -> 5988.1 | H16: =Historical!H99 -> -1839.7 | I16: ='Balance Sheet'!H18-'Balance Sheet'!I18 -> -29349.118 | J16: ='Balance Sheet'!I18-'Balance Sheet'!J18 -> -13178.242 | K16: ='Balance Sheet'!J18-'Balance Sheet'!K18 -> -14496.066 | L16: ='Balance Sheet'!K18-'Balance Sheet'!L18 -> -15945.673 | M16: ='Balance Sheet'!L18-'Balance Sheet'!M18 -> -17540.24 | N16: ='Balance Sheet'!M18-'Balance Sheet'!N18 -> -16062.475 | O16: ='Balance Sheet'!N18-'Balance Sheet'!O18 -> -14485.23 | P16: ='Balance Sheet'!O18-'Balance Sheet'!P18 -> -12894.707 | ... R16: ='Balance Sheet'!Q18-'Balance Sheet'!R18 -> -9906.4044
B17: =Historical!B100 -> Trade receivables | D17: =Historical!D100 -> 937.3 | E17: =Historical!E100 -> -13422.6 | F17: =Historical!F100 -> -9531.7 | G17: =Historical!G100 -> 3528.9 | H17: =Historical!H100 -> -16020.5 | I17: ='Balance Sheet'!H20-'Balance Sheet'!I20 -> -18210.041 | J17: ='Balance Sheet'!I20-'Balance Sheet'!J20 -> -14867.114 | K17: ='Balance Sheet'!J20-'Balance Sheet'!K20 -> -16353.826 | L17: ='Balance Sheet'!K20-'Balance Sheet'!L20 -> -17989.208 | M17: ='Balance Sheet'!L20-'Balance Sheet'!M20 -> -19788.129 | N17: ='Balance Sheet'!M20-'Balance Sheet'!N20 -> -18120.979 | O17: ='Balance Sheet'!N20-'Balance Sheet'!O20 -> -16341.601 | P17: ='Balance Sheet'!O20-'Balance Sheet'!P20 -> -14547.243 | ... R17: ='Balance Sheet'!Q20-'Balance Sheet'!R20 -> -11175.971
B18: =Historical!B101 -> Other assets | D18: =Historical!D101 -> 1166.2 | E18: =Historical!E101 -> 141.1 | F18: =Historical!F101 -> -2158.1 | G18: =Historical!G101 -> -3839 | H18: =Historical!H101 -> -593.2 | I18: =-(SUM('Balance Sheet'!I19,'Balance Sheet'!I23:I25)-SUM('Balance Sheet'!H19,'Balance Sheet'!H23:H25)) -> 0 | J18: =-(SUM('Balance Sheet'!J19,'Balance Sheet'!J23:J25)-SUM('Balance Sheet'!I19,'Balance Sheet'!I23:I25)) -> 0 | K18: =-(SUM('Balance Sheet'!K19,'Balance Sheet'!K23:K25)-SUM('Balance Sheet'!J19,'Balance Sheet'!J23:J25)) -> 0 | L18: =-(SUM('Balance Sheet'!L19,'Balance Sheet'!L23:L25)-SUM('Balance Sheet'!K19,'Balance Sheet'!K23:K25)) -> 0 | M18: =-(SUM('Balance Sheet'!M19,'Balance Sheet'!M23:M25)-SUM('Balance Sheet'!L19,'Balance Sheet'!L23:L25)) -> 0 | N18: =-(SUM('Balance Sheet'!N19,'Balance Sheet'!N23:N25)-SUM('Balance Sheet'!M19,'Balance Sheet'!M23:M25)) -> 0 | O18: =-(SUM('Balance Sheet'!O19,'Balance Sheet'!O23:O25)-SUM('Balance Sheet'!N19,'Balance Sheet'!N23:N25)) -> 0 | P18: =-(SUM('Balance Sheet'!P19,'Balance Sheet'!P23:P25)-SUM('Balance Sheet'!O19,'Balance Sheet'!O23:O25)) -> 0 | ... R18: =-(SUM('Balance Sheet'!R19,'Balance Sheet'!R23:R25)-SUM('Balance Sheet'!Q19,'Balance Sheet'!Q23:Q25)) -> 0
B19: =Historical!B102 -> Trade payables | D19: =Historical!D102 -> 3814.6 | E19: =Historical!E102 -> 3699.2 | F19: =Historical!F102 -> 11823.7 | G19: =Historical!G102 -> 2497.2 | H19: =Historical!H102 -> 5279.7 | I19: ='Balance Sheet'!I48-'Balance Sheet'!H48 -> 8025.4336 | J19: ='Balance Sheet'!J48-'Balance Sheet'!I48 -> 6986.8834 | K19: ='Balance Sheet'!K48-'Balance Sheet'!J48 -> 7685.5717 | L19: ='Balance Sheet'!L48-'Balance Sheet'!K48 -> 8454.1289 | M19: ='Balance Sheet'!M48-'Balance Sheet'!L48 -> 9299.5418 | N19: ='Balance Sheet'!N48-'Balance Sheet'!M48 -> 8516.0554 | O19: ='Balance Sheet'!O48-'Balance Sheet'!N48 -> 7679.8266 | P19: ='Balance Sheet'!P48-'Balance Sheet'!O48 -> 6836.5581 | ... R19: ='Balance Sheet'!R48-'Balance Sheet'!Q48 -> 5252.2099
B20: =Historical!B103 -> Other liabilities | D20: =Historical!D103 -> 24983.5 | E20: =Historical!E103 -> -23333.5 | F20: =Historical!F103 -> -6691.5 | G20: =Historical!G103 -> 2409.2 | H20: =Historical!H103 -> 1820.3 | I20: =(SUM('Balance Sheet'!I46,'Balance Sheet'!I47,'Balance Sheet'!I49,'Balance Sheet'!I51)-SUM('Balance Sheet'!H46,'Balance Sheet'!H47,'Balance Sheet'!H49,'Balance Sheet'!H51)) -> 0 | J20: =(SUM('Balance Sheet'!J46,'Balance Sheet'!J47,'Balance Sheet'!J49,'Balance Sheet'!J51)-SUM('Balance Sheet'!I46,'Balance Sheet'!I47,'Balance Sheet'!I49,'Balance Sheet'!I51)) -> 0 | K20: =(SUM('Balance Sheet'!K46,'Balance Sheet'!K47,'Balance Sheet'!K49,'Balance Sheet'!K51)-SUM('Balance Sheet'!J46,'Balance Sheet'!J47,'Balance Sheet'!J49,'Balance Sheet'!J51)) -> 0 | L20: =(SUM('Balance Sheet'!L46,'Balance Sheet'!L47,'Balance Sheet'!L49,'Balance Sheet'!L51)-SUM('Balance Sheet'!K46,'Balance Sheet'!K47,'Balance Sheet'!K49,'Balance Sheet'!K51)) -> 0 | M20: =(SUM('Balance Sheet'!M46,'Balance Sheet'!M47,'Balance Sheet'!M49,'Balance Sheet'!M51)-SUM('Balance Sheet'!L46,'Balance Sheet'!L47,'Balance Sheet'!L49,'Balance Sheet'!L51)) -> 0 | N20: =(SUM('Balance Sheet'!N46,'Balance Sheet'!N47,'Balance Sheet'!N49,'Balance Sheet'!N51)-SUM('Balance Sheet'!M46,'Balance Sheet'!M47,'Balance Sheet'!M49,'Balance Sheet'!M51)) -> 0 | O20: =(SUM('Balance Sheet'!O46,'Balance Sheet'!O47,'Balance Sheet'!O49,'Balance Sheet'!O51)-SUM('Balance Sheet'!N46,'Balance Sheet'!N47,'Balance Sheet'!N49,'Balance Sheet'!N51)) -> 0 | P20: =(SUM('Balance Sheet'!P46,'Balance Sheet'!P47,'Balance Sheet'!P49,'Balance Sheet'!P51)-SUM('Balance Sheet'!O46,'Balance Sheet'!O47,'Balance Sheet'!O49,'Balance Sheet'!O51)) -> 0 | ... R20: =(SUM('Balance Sheet'!R46,'Balance Sheet'!R47,'Balance Sheet'!R49,'Balance Sheet'!R51)-SUM('Balance Sheet'!Q46,'Balance Sheet'!Q47,'Balance Sheet'!Q49,'Balance Sheet'!Q51)) -> 0
B21: =Historical!B104 -> Provisions | D21: =Historical!D104 -> 5542.2 | E21: =Historical!E104 -> 45436.8 | F21: =Historical!F104 -> -38038.6 | G21: =Historical!G104 -> 36.9 | H21: =Historical!H104 -> 8117.8 | I21: ='Balance Sheet'!I50-'Balance Sheet'!H50 -> 0 | J21: ='Balance Sheet'!J50-'Balance Sheet'!I50 -> 0 | K21: ='Balance Sheet'!K50-'Balance Sheet'!J50 -> 0 | L21: ='Balance Sheet'!L50-'Balance Sheet'!K50 -> 0 | M21: ='Balance Sheet'!M50-'Balance Sheet'!L50 -> 0 | N21: ='Balance Sheet'!N50-'Balance Sheet'!M50 -> 0 | O21: ='Balance Sheet'!O50-'Balance Sheet'!N50 -> 0 | P21: ='Balance Sheet'!P50-'Balance Sheet'!O50 -> 0 | ... R21: ='Balance Sheet'!R50-'Balance Sheet'!Q50 -> 0
B22: =Historical!B105 -> Cash from operations | D22: =SUM(D14:D21) -> 71733.1 | E22: =SUM(E14:E21) -> 80153.2 | F22: =SUM(F14:F21) -> 64691.7 | G22: =SUM(G14:G21) -> 137044.2 | H22: =SUM(H14:H21) -> 145489.3 | I22: =SUM(I14:I21) -> 115212.88 | J22: =SUM(J14:J21) -> 149162.8 | K22: =SUM(K14:K21) -> 164079.08 | ... R22: =SUM(R14:R21) -> 286712.42
B23: =Historical!B106 -> Tax paid (net) | D23: =Historical!D106 -> -10029.4 | E23: =Historical!E106 -> 9692.2 | F23: =Historical!F106 -> -15098.4 | G23: =Historical!G106 -> -15694.4 | H23: =Historical!H106 -> -4768.4 | I23: =-'Income Statement'!H20 -> -28176.4 | J23: =-'Income Statement'!I20 -> -31629.392 | K23: =-'Income Statement'!J20 -> -35694.627 | L23: =-'Income Statement'!K20 -> -39862.157 | M23: =-'Income Statement'!L20 -> -44815.199 | N23: =-'Income Statement'!M20 -> -49034.858 | O23: =-'Income Statement'!N20 -> -53304.97 | P23: =-'Income Statement'!O20 -> -56720.774 | ... R23: =-'Income Statement'!Q20 -> -62892.321
B24: =Historical!B107 -> Net Cash from Operating (A) | D24: =D22+D23 -> 61703.7 | E24: =E22+E23 -> 89845.4 | F24: =F22+F23 -> 49593.3 | G24: =G22+G23 -> 121349.8 | H24: =H22+H23 -> 140720.9 | I24: =I22+I23 -> 87036.483 | J24: =J22+J23 -> 117533.4 | K24: =K22+K23 -> 128384.45 | ... R24: =R22+R23 -> 223820.1
B25: =Historical!B108 -> B. Cash Flow from Investing Activities
B26: =Historical!B109 -> Purchase of PP&E | D26: =Historical!D109 -> -11701.3 | E26: =Historical!E109 -> -14950.4 | F26: =Historical!F109 -> -20855.8 | G26: =Historical!G109 -> -22018.1 | H26: =Historical!H109 -> -21285.8 | I26: =-Schedules!H19 -> -24015.375 | J26: =-Schedules!I19 -> -24135.452 | K26: =-Schedules!J19 -> -24256.129 | L26: =-Schedules!K19 -> -24377.41 | M26: =-Schedules!L19 -> -24499.297 | N26: =-Schedules!M19 -> -24621.793 | O26: =-Schedules!N19 -> -24744.902 | P26: =-Schedules!O19 -> -24868.627 | ... R26: =-Schedules!Q19 -> -25117.935
B27: =Historical!B110 -> Sale of PP&E | D27: =Historical!D110 -> 971 | E27: =Historical!E110 -> 606.1 | F27: =Historical!F110 -> 210.1 | G27: =Historical!G110 -> 308.4 | H27: =Historical!H110 -> 610.1 | I27: 0 | J27: 0 | K27: 0 | L27: 0 | M27: 0 | N27: 0 | O27: 0 | P27: 0 | Q27: 0 | R27: 0
B28: =Historical!B111 -> Investments (net) | D28: =Historical!D111 -> 11670.6 | E28: =Historical!E111 -> -34485.4 | F28: =Historical!F111 -> -10673.9 | G28: =Historical!G111 -> 10034.3 | H28: =Historical!H111 -> -28911.6 | I28: 0 | J28: 0 | K28: 0 | L28: 0 | M28: 0 | N28: 0 | O28: 0 | P28: 0 | Q28: 0 | R28: 0
B29: =Historical!B112 -> Acquisition/Diaposal of subsidiary (net) | D29: =Historical!D112 -> -616 | E29: =Historical!E112 -> -7157.3 | F29: =Historical!F112 -> -46858.2 | G29: =Historical!G112 -> -1433.2 | H29: =Historical!H112 -> -2728.3 | I29: 0 | J29: 0 | K29: 0 | L29: 0 | M29: 0 | N29: 0 | O29: 0 | P29: 0 | Q29: 0 | R29: 0
B30: =Historical!B113 -> Interest & dividend received | D30: =Historical!D113 -> 2093.6 | E30: =Historical!E113 -> 2101.3 | F30: =Historical!F113 -> 4503.3 | G30: =Historical!G113 -> 7123.4 | H30: =Historical!H113 -> 8697.7 | I30: ='Income Statement'!H18 -> 10442.099 | J30: ='Income Statement'!I18 -> 11486.309 | K30: ='Income Statement'!J18 -> 12634.94 | L30: ='Income Statement'!K18 -> 13898.434 | M30: ='Income Statement'!L18 -> 15288.278 | N30: ='Income Statement'!M18 -> 16561.027 | O30: ='Income Statement'!N18 -> 17708.799 | P30: ='Income Statement'!O18 -> 18730.542 | ... R30: ='Income Statement'!Q18 -> 20415.179
B31: =Historical!B114 -> Other investing flows | D31: =Historical!D114 -> 2944.3 | E31: =Historical!E114 -> -3361.7 | F31: =Historical!F114 -> -5762.3 | G31: =Historical!G114 -> -916.7 | H31: =Historical!H114 -> -9443.7 | I31: 0 | J31: 0 | K31: 0 | L31: 0 | M31: 0 | N31: 0 | O31: 0 | P31: 0 | Q31: 0 | R31: 0
B32: =Historical!B115 -> Net Cash from Investing (B) | D32: =SUM(D26:D31) -> 5362.2 | E32: =SUM(E26:E31) -> -57247.4 | F32: =SUM(F26:F31) -> -79436.8 | G32: =SUM(G26:G31) -> -6901.9 | H32: =SUM(H26:H31) -> -53061.6 | I32: =SUM(I26:I31) -> -13573.276 | J32: =SUM(J26:J31) -> -12649.143 | K32: =SUM(K26:K31) -> -11621.189 | ... R32: =SUM(R26:R31) -> -4702.7561
B33: =Historical!B116 -> C. Cash Flow from Financing Activities
B34: =Historical!B117 -> Borrowings (net) | D34: =Historical!D117 -> -41992.1 | E34: =Historical!E117 -> -27431.3 | F34: =Historical!F117 -> 52601.5 | G34: =Historical!G117 -> -35329.4 | H34: =Historical!H117 -> -9821.4 | I34: =Schedules!H25 -> 0 | J34: =Schedules!I25 -> 0 | K34: =Schedules!J25 -> 0 | L34: =Schedules!K25 -> 0 | M34: =Schedules!L25 -> 0 | N34: =Schedules!M25 -> 0 | O34: =Schedules!N25 -> 0 | P34: =Schedules!O25 -> 0 | ... R34: =Schedules!Q25 -> 0
